Traceback (most recent call last):
  File "./task3.py", line 4, in <module>
    raise Exception()
Exception
